<?xml version="1.0" encoding="utf-8"?>
<!-- This URDF was automatically created by SolidWorks to URDF Exporter! Originally created by Stephen Brawner (brawner@gmail.com) 
     Commit Version: 1.6.0-4-g7f85cfe  Build Version: 1.6.7995.38578
     For more information, please see http://wiki.ros.org/sw_urdf_exporter -->
<robot
  name="Cerberus">
  <link
    name="M">
    <inertial>
      <origin
        xyz="-0.00010103 0.00010381 0.011864"
        rpy="0 0 0" />
      <mass
        value="0.22682" />
      <inertia
        ixx="0.00042387"
        ixy="-2.5784E-08"
        ixz="2.5068E-08"
        iyy="0.00081476"
        iyz="-3.9138E-08"
        izz="0.0012174" />
    </inertial>
    <visual>
      <origin
        xyz="0 0 0"
        rpy="0 0 0" />
      <geometry>
        <mesh
          filename="package://Cerberus/meshes/M.STL" />
      </geometry>
      <material
        name="">
        <color
          rgba="0.50196 0.50196 0.50196 1" />
        <texture
          filename="package://Cerberus/textures/DarkBlackPlastic.png" />
      </material>
    </visual>
    <collision>
      <origin
        xyz="0 0 0"
        rpy="0 0 0" />
      <geometry>
        <mesh
          filename="package://Cerberus/meshes/M.STL" />
      </geometry>
    </collision>
  </link>
  <link
    name="BODY">
    <inertial>
      <origin
        xyz="-0.0095362 3.6843E-06 0.067699"
        rpy="0 0 0" />
      <mass
        value="0.89733" />
      <inertia
        ixx="0.0071385"
        ixy="1.9491E-08"
        ixz="-0.00055617"
        iyy="0.0040392"
        iyz="-7.5384E-08"
        izz="0.0076279" />
    </inertial>
    <visual>
      <origin
        xyz="0 0 0"
        rpy="0 0 0" />
      <geometry>
        <mesh
          filename="package://Cerberus/meshes/BODY.STL" />
      </geometry>
      <material
        name="">
        <color
          rgba="1 0 1 1" />
        <texture
          filename="package://Cerberus/textures/PurplePlastic.jpg" />
      </material>
    </visual>
    <collision>
      <origin
        xyz="0 0 0"
        rpy="0 0 0" />
      <geometry>
        <mesh
          filename="package://Cerberus/meshes/BODY.STL" />
      </geometry>
    </collision>
  </link>
  <joint
    name="BODY_M"
    type="fixed">
    <origin
      xyz="0.05 0 0.003"
      rpy="0 0 0" />
    <parent
      link="M" />
    <child
      link="BODY" />
    <axis
      xyz="0 0 0" />
  </joint>
  <link
    name="CAMERA">
    <inertial>
      <origin
        xyz="-0.026968 -8.3224E-06 -0.016758"
        rpy="0 0 0" />
      <mass
        value="0.29652" />
      <inertia
        ixx="0.00045957"
        ixy="4.4891E-08"
        ixz="-1.0134E-05"
        iyy="0.00013644"
        iyz="-1.4484E-09"
        izz="0.0005175" />
    </inertial>
    <visual>
      <origin
        xyz="0 0 0"
        rpy="0 0 0" />
      <geometry>
        <mesh
          filename="package://Cerberus/meshes/CAMERA.STL" />
      </geometry>
      <material
        name="">
        <color
          rgba="0.10196 0.10196 0.10196 1" />
        <texture
          filename="package://Cerberus/textures/LightBlackPlastic.png" />
      </material>
    </visual>
    <collision>
      <origin
        xyz="0 0 0"
        rpy="0 0 0" />
      <geometry>
        <mesh
          filename="package://Cerberus/meshes/CAMERA.STL" />
      </geometry>
    </collision>
  </link>
  <joint
    name="CAMERA_M"
    type="fixed">
    <origin
      xyz="0.20487 0 0.09815"
      rpy="0 0 0" />
    <parent
      link="M" />
    <child
      link="CAMERA" />
    <axis
      xyz="0 0 0" />
  </joint>
  <link
    name="LIDAR">
    <inertial>
      <origin
        xyz="0.0021649 0.00030541 -0.0028881"
        rpy="0 0 0" />
      <mass
        value="0.10467" />
      <inertia
        ixx="0.00011985"
        ixy="-2.5264E-08"
        ixz="9.903E-09"
        iyy="7.902E-05"
        iyz="4.2071E-08"
        izz="0.0001916" />
    </inertial>
    <visual>
      <origin
        xyz="0 0 0"
        rpy="0 0 0" />
      <geometry>
        <mesh
          filename="package://Cerberus/meshes/LIDAR.STL" />
      </geometry>
      <material
        name="">
        <color
          rgba="0.79216 0.81961 0.93333 1" />
        <texture
          filename="package://Cerberus/textures/LightBlackPlastic.png" />
      </material>
    </visual>
    <collision>
      <origin
        xyz="0 0 0"
        rpy="0 0 0" />
      <geometry>
        <mesh
          filename="package://Cerberus/meshes/LIDAR.STL" />
      </geometry>
    </collision>
  </link>
  <joint
    name="LIDAR_M"
    type="fixed">
    <origin
      xyz="0.047975 2.5E-05 0.14436"
      rpy="0 0 0" />
    <parent
      link="M" />
    <child
      link="LIDAR" />
    <axis
      xyz="0 0 0" />
  </joint>
  <link
    name="IMU0C">
    <inertial>
      <origin
        xyz="-6.9389E-18 1.8955E-19 0.0015"
        rpy="0 0 0" />
      <mass
        value="0.0009" />
      <inertia
        ixx="1.755E-08"
        ixy="4.9226E-41"
        ixz="-6.9022E-25"
        iyy="3.0675E-08"
        iyz="1.8889E-25"
        izz="4.6875E-08" />
    </inertial>
    <visual>
      <origin
        xyz="0 0 0"
        rpy="0 0 0" />
      <geometry>
        <mesh
          filename="package://Cerberus/meshes/IMU0C.STL" />
      </geometry>
      <material
        name="">
        <color
          rgba="0 1 0 1" />
      </material>
    </visual>
    <collision>
      <origin
        xyz="0 0 0"
        rpy="0 0 0" />
      <geometry>
        <mesh
          filename="package://Cerberus/meshes/IMU0C.STL" />
      </geometry>
    </collision>
  </link>
  <joint
    name="IMU0C_M"
    type="fixed">
    <origin
      xyz="0.05 0 0.12916"
      rpy="0 0 0" />
    <parent
      link="M" />
    <child
      link="IMU0C" />
    <axis
      xyz="0 0 0" />
  </joint>
  <link
    name="SeFR">
    <inertial>
      <origin
        xyz="0.00022279 0.00033706 0.023497"
        rpy="0 0 0" />
      <mass
        value="0.029079" />
      <inertia
        ixx="3.9251E-06"
        ixy="6.5626E-09"
        ixz="-9.8203E-09"
        iyy="4.0186E-06"
        iyz="-6.2671E-09"
        izz="2.6804E-06" />
    </inertial>
    <visual>
      <origin
        xyz="0 0 0"
        rpy="0 0 0" />
      <geometry>
        <mesh
          filename="package://Cerberus/meshes/SeFR.STL" />
      </geometry>
      <material
        name="">
        <color
          rgba="0.89804 0.91765 0.92941 1" />
        <texture
          filename="package://Cerberus/textures/DarkBlackPlastic.png" />
      </material>
    </visual>
    <collision>
      <origin
        xyz="0 0 0"
        rpy="0 0 0" />
      <geometry>
        <mesh
          filename="package://Cerberus/meshes/SeFR.STL" />
      </geometry>
    </collision>
  </link>
  <joint
    name="SeFR_M"
    type="revolute">
    <origin
      xyz="0.1196 -0.095 0.044"
      rpy="3.1416 1.5707 3.1416" />
    <parent
      link="M" />
    <child
      link="SeFR" />
    <axis
      xyz="0.00011373 0 -1" />
    <limit
      lower="-2.0944"
      upper="2.0944"
      effort="1.471"
      velocity="5.8178" />
    <dynamics
      damping="0.02"
      friction="0.1" />
    <safety_controller
      soft_upper_limit="2.05"
      soft_lower_limit="-2.05"
      k_velocity="0" />
  </joint>
  <link
    name="ThFR">
    <inertial>
      <origin
        xyz="0.065617 -0.006527 0.024512"
        rpy="0 0 0" />
      <mass
        value="0.24964" />
      <inertia
        ixx="5.1153E-05"
        ixy="2.3468E-05"
        ixz="-5.2194E-06"
        iyy="0.00072109"
        iyz="-7.7661E-07"
        izz="0.00073416" />
    </inertial>
    <visual>
      <origin
        xyz="0 0 0"
        rpy="0 0 0" />
      <geometry>
        <mesh
          filename="package://Cerberus/meshes/ThFR.STL" />
      </geometry>
      <material
        name="">
        <color
          rgba="0.62745 0.62745 0.62745 1" />
        <texture
          filename="package://Cerberus/textures/DarkBlackPlastic.png" />
      </material>
    </visual>
    <collision>
      <origin
        xyz="0 0 0"
        rpy="0 0 0" />
      <geometry>
        <mesh
          filename="package://Cerberus/meshes/ThFR.STL" />
      </geometry>
    </collision>
  </link>
  <joint
    name="ThFR_SeFR"
    type="revolute">
    <origin
      xyz="2.2896E-05 -0.0144 0.045901"
      rpy="1.5708 0.70743 0" />
    <parent
      link="SeFR" />
    <child
      link="ThFR" />
    <axis
      xyz="0 0 -1" />
    <limit
      lower="-2.0944"
      upper="2.0944"
      effort="1.471"
      velocity="5.8178" />
    <dynamics
      damping="0.02"
      friction="0.1" />
    <safety_controller
      soft_upper_limit="2.05"
      soft_lower_limit="-2.05"
      k_velocity="0" />
  </joint>
  <link
    name="ArFR">
    <inertial>
      <origin
        xyz="2.7735E-05 -0.007627 0.0033028"
        rpy="0 0 0" />
      <mass
        value="0.0030347" />
      <inertia
        ixx="2.989E-07"
        ixy="4.865E-09"
        ixz="-2.5487E-11"
        iyy="4.3267E-08"
        iyz="5.0977E-09"
        izz="3.2577E-07" />
    </inertial>
    <visual>
      <origin
        xyz="0 0 0"
        rpy="0 0 0" />
      <geometry>
        <mesh
          filename="package://Cerberus/meshes/ArFR.STL" />
      </geometry>
      <material
        name="">
        <color
          rgba="0.89804 0.91765 0.92941 1" />
        <texture
          filename="package://Cerberus/textures/MetalSteel.png" />
      </material>
    </visual>
    <collision>
      <origin
        xyz="0 0 0"
        rpy="0 0 0" />
      <geometry>
        <mesh
          filename="package://Cerberus/meshes/ArFR.STL" />
      </geometry>
    </collision>
  </link>
  <joint
    name="ArFR_ThFR"
    type="revolute">
    <origin
      xyz="0.050268 -0.027324 0.025223"
      rpy="-1.5708 0 3.1416" />
    <parent
      link="ThFR" />
    <child
      link="ArFR" />
    <axis
      xyz="0 0 -1" />
    <limit
      lower="-2.0944"
      upper="2.0944"
      effort="1.471"
      velocity="5.8178" />
    <dynamics
      damping="0.02"
      friction="0.1" />
    <safety_controller
      soft_upper_limit="2.05"
      soft_lower_limit="-2.05"
      k_velocity="0" />
  </joint>
  <link
    name="IMU1FR">
    <inertial>
      <origin
        xyz="0 -1.3878E-17 0.0015"
        rpy="0 0 0" />
      <mass
        value="0.0009" />
      <inertia
        ixx="1.755E-08"
        ixy="-4.9631E-24"
        ixz="-1.6578E-24"
        iyy="3.0675E-08"
        iyz="4.867E-25"
        izz="4.6875E-08" />
    </inertial>
    <visual>
      <origin
        xyz="0 0 0"
        rpy="0 0 0" />
      <geometry>
        <mesh
          filename="package://Cerberus/meshes/IMU1FR.STL" />
      </geometry>
      <material
        name="">
        <color
          rgba="0 1 0 1" />
      </material>
    </visual>
    <collision>
      <origin
        xyz="0 0 0"
        rpy="0 0 0" />
      <geometry>
        <mesh
          filename="package://Cerberus/meshes/IMU1FR.STL" />
      </geometry>
    </collision>
  </link>
  <joint
    name="IMU1FR_ThFR"
    type="fixed">
    <origin
      xyz="0.079757 -0.006231 0.04015"
      rpy="0 0 3.0636" />
    <parent
      link="ThFR" />
    <child
      link="IMU1FR" />
    <axis
      xyz="0 0 0" />
  </joint>
  <link
    name="ShFR">
    <inertial>
      <origin
        xyz="-0.065758 -0.007629 0.014842"
        rpy="0 0 0" />
      <mass
        value="0.10028" />
      <inertia
        ixx="1.1372E-05"
        ixy="-2.0704E-05"
        ixz="4.5005E-09"
        iyy="0.00027852"
        iyz="1.4244E-10"
        izz="0.00028532" />
    </inertial>
    <visual>
      <origin
        xyz="0 0 0"
        rpy="0 0 0" />
      <geometry>
        <mesh
          filename="package://Cerberus/meshes/ShFR.STL" />
      </geometry>
      <material
        name="">
        <color
          rgba="0.50196 0.50196 0.50196 1" />
        <texture
          filename="package://Cerberus/textures/DarkBlackPlastic.png" />
      </material>
    </visual>
    <collision>
      <origin
        xyz="0 0 0"
        rpy="0 0 0" />
      <geometry>
        <mesh
          filename="package://Cerberus/meshes/ShFR.STL" />
      </geometry>
    </collision>
  </link>
  <joint
    name="ShFR_ThFR"
    type="revolute">
    <origin
      xyz="0.18101 0.0059195 0.01015"
      rpy="0 0 -1.6488" />
    <parent
      link="ThFR" />
    <child
      link="ShFR" />
    <axis
      xyz="0 0 -1" />
    <limit
      lower="-2.0944"
      upper="2.0944"
      effort="1.471"
      velocity="5.8178" />
    <dynamics
      damping="0.02"
      friction="0.1" />
    <safety_controller
      soft_upper_limit="2.05"
      soft_lower_limit="-2.05"
      k_velocity="0" />
    <mimic
      joint="ArFR_ThFR"
      multiplier="-0.304"
      offset="0" />
  </joint>
  <link
    name="IMU2FR">
    <inertial>
      <origin
        xyz="0 -2.7756E-17 0.0015"
        rpy="0 0 0" />
      <mass
        value="0.0009" />
      <inertia
        ixx="1.755E-08"
        ixy="-3.4121E-23"
        ixz="5.5831E-25"
        iyy="3.0675E-08"
        iyz="-8.4377E-24"
        izz="4.6875E-08" />
    </inertial>
    <visual>
      <origin
        xyz="0 0 0"
        rpy="0 0 0" />
      <geometry>
        <mesh
          filename="package://Cerberus/meshes/IMU2FR.STL" />
      </geometry>
      <material
        name="">
        <color
          rgba="0 1 0 1" />
      </material>
    </visual>
    <collision>
      <origin
        xyz="0 0 0"
        rpy="0 0 0" />
      <geometry>
        <mesh
          filename="package://Cerberus/meshes/IMU2FR.STL" />
      </geometry>
    </collision>
  </link>
  <joint
    name="IMU2FR_ShFR"
    type="fixed">
    <origin
      xyz="-0.16803 0.013888 0.024775"
      rpy="0 0 -0.76282" />
    <parent
      link="ShFR" />
    <child
      link="IMU2FR" />
    <axis
      xyz="0 0 0" />
  </joint>
  <link
    name="SeBR">
    <inertial>
      <origin
        xyz="0.00022279 0.00033706 0.023497"
        rpy="0 0 0" />
      <mass
        value="0.029079" />
      <inertia
        ixx="3.9251E-06"
        ixy="6.5626E-09"
        ixz="-9.8203E-09"
        iyy="4.0186E-06"
        iyz="-6.2671E-09"
        izz="2.6804E-06" />
    </inertial>
    <visual>
      <origin
        xyz="0 0 0"
        rpy="0 0 0" />
      <geometry>
        <mesh
          filename="package://Cerberus/meshes/SeBR.STL" />
      </geometry>
      <material
        name="">
        <color
          rgba="0.89804 0.91765 0.92941 1" />
        <texture
          filename="package://Cerberus/textures/DarkBlackPlastic.png" />
      </material>
    </visual>
    <collision>
      <origin
        xyz="0 0 0"
        rpy="0 0 0" />
      <geometry>
        <mesh
          filename="package://Cerberus/meshes/SeBR.STL" />
      </geometry>
    </collision>
  </link>
  <joint
    name="SeBR_M"
    type="revolute">
    <origin
      xyz="-0.0904 -0.095 0.044"
      rpy="3.1416 1.5707 3.1416" />
    <parent
      link="M" />
    <child
      link="SeBR" />
    <axis
      xyz="0.00011373 0 -1" />
    <limit
      lower="-2.0944"
      upper="2.0944"
      effort="1.471"
      velocity="5.8178" />
    <dynamics
      damping="0.02"
      friction="0.1" />
    <safety_controller
      soft_upper_limit="2.05"
      soft_lower_limit="-2.05"
      k_velocity="0" />
  </joint>
  <link
    name="ThBR">
    <inertial>
      <origin
        xyz="0.065617 -0.006527 0.024512"
        rpy="0 0 0" />
      <mass
        value="0.24964" />
      <inertia
        ixx="5.1153E-05"
        ixy="2.3468E-05"
        ixz="-5.2194E-06"
        iyy="0.00072109"
        iyz="-7.7661E-07"
        izz="0.00073416" />
    </inertial>
    <visual>
      <origin
        xyz="0 0 0"
        rpy="0 0 0" />
      <geometry>
        <mesh
          filename="package://Cerberus/meshes/ThBR.STL" />
      </geometry>
      <material
        name="">
        <color
          rgba="0.62745 0.62745 0.62745 1" />
        <texture
          filename="package://Cerberus/textures/DarkBlackPlastic.png" />
      </material>
    </visual>
    <collision>
      <origin
        xyz="0 0 0"
        rpy="0 0 0" />
      <geometry>
        <mesh
          filename="package://Cerberus/meshes/ThBR.STL" />
      </geometry>
    </collision>
  </link>
  <joint
    name="ThBR_SeBR"
    type="revolute">
    <origin
      xyz="2.2896E-05 -0.0144 0.045901"
      rpy="1.5708 0.70743 0" />
    <parent
      link="SeBR" />
    <child
      link="ThBR" />
    <axis
      xyz="0 0 -1" />
    <limit
      lower="-2.0944"
      upper="2.0944"
      effort="1.471"
      velocity="5.8178" />
    <dynamics
      damping="0.02"
      friction="0.1" />
    <safety_controller
      soft_upper_limit="2.05"
      soft_lower_limit="-2.05"
      k_velocity="0" />
  </joint>
  <link
    name="ArBR">
    <inertial>
      <origin
        xyz="2.7735E-05 -0.007627 0.0033028"
        rpy="0 0 0" />
      <mass
        value="0.0030347" />
      <inertia
        ixx="2.989E-07"
        ixy="4.865E-09"
        ixz="-2.5487E-11"
        iyy="4.3267E-08"
        iyz="5.0977E-09"
        izz="3.2577E-07" />
    </inertial>
    <visual>
      <origin
        xyz="0 0 0"
        rpy="0 0 0" />
      <geometry>
        <mesh
          filename="package://Cerberus/meshes/ArBR.STL" />
      </geometry>
      <material
        name="">
        <color
          rgba="0.89804 0.91765 0.92941 1" />
        <texture
          filename="package://Cerberus/textures/MetalSteel.png" />
      </material>
    </visual>
    <collision>
      <origin
        xyz="0 0 0"
        rpy="0 0 0" />
      <geometry>
        <mesh
          filename="package://Cerberus/meshes/ArBR.STL" />
      </geometry>
    </collision>
  </link>
  <joint
    name="ArBR_ThBR"
    type="revolute">
    <origin
      xyz="0.050268 -0.027324 0.025223"
      rpy="-1.5708 0 3.1416" />
    <parent
      link="ThBR" />
    <child
      link="ArBR" />
    <axis
      xyz="0 0 -1" />
    <limit
      lower="-2.0944"
      upper="2.0944"
      effort="1.471"
      velocity="5.8178" />
    <dynamics
      damping="0.02"
      friction="0.1" />
    <safety_controller
      soft_upper_limit="2.05"
      soft_lower_limit="-2.05"
      k_velocity="0" />
  </joint>
  <link
    name="IMU1BR">
    <inertial>
      <origin
        xyz="0 -1.3878E-17 0.0015"
        rpy="0 0 0" />
      <mass
        value="0.0009" />
      <inertia
        ixx="1.755E-08"
        ixy="-8.2718E-25"
        ixz="-2.4676E-24"
        iyy="3.0675E-08"
        iyz="2.5064E-24"
        izz="4.6875E-08" />
    </inertial>
    <visual>
      <origin
        xyz="0 0 0"
        rpy="0 0 0" />
      <geometry>
        <mesh
          filename="package://Cerberus/meshes/IMU1BR.STL" />
      </geometry>
      <material
        name="">
        <color
          rgba="0 1 0 1" />
      </material>
    </visual>
    <collision>
      <origin
        xyz="0 0 0"
        rpy="0 0 0" />
      <geometry>
        <mesh
          filename="package://Cerberus/meshes/IMU1BR.STL" />
      </geometry>
    </collision>
  </link>
  <joint
    name="IMU1BR_ThBR"
    type="fixed">
    <origin
      xyz="0.079757 -0.006231 0.04015"
      rpy="0 0 3.0636" />
    <parent
      link="ThBR" />
    <child
      link="IMU1BR" />
    <axis
      xyz="0 0 0" />
  </joint>
  <link
    name="ShBR">
    <inertial>
      <origin
        xyz="-0.065758 -0.007629 0.014842"
        rpy="0 0 0" />
      <mass
        value="0.10028" />
      <inertia
        ixx="1.1372E-05"
        ixy="-2.0704E-05"
        ixz="4.5006E-09"
        iyy="0.00027852"
        iyz="1.425E-10"
        izz="0.00028532" />
    </inertial>
    <visual>
      <origin
        xyz="0 0 0"
        rpy="0 0 0" />
      <geometry>
        <mesh
          filename="package://Cerberus/meshes/ShBR.STL" />
      </geometry>
      <material
        name="">
        <color
          rgba="0.50196 0.50196 0.50196 1" />
        <texture
          filename="package://Cerberus/textures/DarkBlackPlastic.png" />
      </material>
    </visual>
    <collision>
      <origin
        xyz="0 0 0"
        rpy="0 0 0" />
      <geometry>
        <mesh
          filename="package://Cerberus/meshes/ShBR.STL" />
      </geometry>
    </collision>
  </link>
  <joint
    name="ShBR_ThBR"
    type="revolute">
    <origin
      xyz="0.18101 0.0059195 0.01015"
      rpy="0 0 -1.6488" />
    <parent
      link="ThBR" />
    <child
      link="ShBR" />
    <axis
      xyz="0 0 -1" />
    <limit
      lower="-2.0944"
      upper="2.0944"
      effort="1.471"
      velocity="5.8178" />
    <dynamics
      damping="0.02"
      friction="0.1" />
    <safety_controller
      soft_upper_limit="2.05"
      soft_lower_limit="-2.05"
      k_velocity="0" />
    <mimic
      joint="ArBR_ThBR"
      multiplier="-0.304"
      offset="0" />
  </joint>
  <link
    name="IMU2BR">
    <inertial>
      <origin
        xyz="0 -6.9389E-18 0.0015"
        rpy="0 0 0" />
      <mass
        value="0.0009" />
      <inertia
        ixx="1.755E-08"
        ixy="-3.3733E-23"
        ixz="7.3958E-25"
        iyy="3.0675E-08"
        iyz="-7.1756E-24"
        izz="4.6875E-08" />
    </inertial>
    <visual>
      <origin
        xyz="0 0 0"
        rpy="0 0 0" />
      <geometry>
        <mesh
          filename="package://Cerberus/meshes/IMU2BR.STL" />
      </geometry>
      <material
        name="">
        <color
          rgba="0 1 0 1" />
      </material>
    </visual>
    <collision>
      <origin
        xyz="0 0 0"
        rpy="0 0 0" />
      <geometry>
        <mesh
          filename="package://Cerberus/meshes/IMU2BR.STL" />
      </geometry>
    </collision>
  </link>
  <joint
    name="IMU2BR_ShBR"
    type="fixed">
    <origin
      xyz="-0.16803 0.013888 0.024775"
      rpy="0 0 -0.76282" />
    <parent
      link="ShBR" />
    <child
      link="IMU2BR" />
    <axis
      xyz="0 0 0" />
  </joint>
  <link
    name="SeFL">
    <inertial>
      <origin
        xyz="0.00022279 0.00033706 0.023497"
        rpy="0 0 0" />
      <mass
        value="0.029079" />
      <inertia
        ixx="3.9251E-06"
        ixy="6.5626E-09"
        ixz="-9.8203E-09"
        iyy="4.0186E-06"
        iyz="-6.2671E-09"
        izz="2.6804E-06" />
    </inertial>
    <visual>
      <origin
        xyz="0 0 0"
        rpy="0 0 0" />
      <geometry>
        <mesh
          filename="package://Cerberus/meshes/SeFL.STL" />
      </geometry>
      <material
        name="">
        <color
          rgba="0.89804 0.91765 0.92941 1" />
        <texture
          filename="package://Cerberus/textures/DarkBlackPlastic.png" />
      </material>
    </visual>
    <collision>
      <origin
        xyz="0 0 0"
        rpy="0 0 0" />
      <geometry>
        <mesh
          filename="package://Cerberus/meshes/SeFL.STL" />
      </geometry>
    </collision>
  </link>
  <joint
    name="SeFL_M"
    type="revolute">
    <origin
      xyz="0.1196 0.095 0.044"
      rpy="0 -1.5707 -3.1416" />
    <parent
      link="M" />
    <child
      link="SeFL" />
    <axis
      xyz="0.00011373 0 -1" />
    <limit
      lower="-2.0944"
      upper="2.0944"
      effort="1.471"
      velocity="5.8178" />
    <dynamics
      damping="0.02"
      friction="0.1" />
    <safety_controller
      soft_upper_limit="2.05"
      soft_lower_limit="-2.05"
      k_velocity="0" />
  </joint>
  <link
    name="ThFL">
    <inertial>
      <origin
        xyz="-0.065617 -0.006527 0.024441"
        rpy="0 0 0" />
      <mass
        value="0.24964" />
      <inertia
        ixx="5.1153E-05"
        ixy="-2.3468E-05"
        ixz="5.239E-06"
        iyy="0.00072109"
        iyz="-7.8973E-07"
        izz="0.00073416" />
    </inertial>
    <visual>
      <origin
        xyz="0 0 0"
        rpy="0 0 0" />
      <geometry>
        <mesh
          filename="package://Cerberus/meshes/ThFL.STL" />
      </geometry>
      <material
        name="">
        <color
          rgba="0.62745 0.62745 0.62745 1" />
        <texture
          filename="package://Cerberus/textures/DarkBlackPlastic.png" />
      </material>
    </visual>
    <collision>
      <origin
        xyz="0 0 0"
        rpy="0 0 0" />
      <geometry>
        <mesh
          filename="package://Cerberus/meshes/ThFL.STL" />
      </geometry>
    </collision>
  </link>
  <joint
    name="ThFL_SeFL"
    type="revolute">
    <origin
      xyz="2.2896E-05 -0.0144 0.045901"
      rpy="1.5708 -0.70743 0" />
    <parent
      link="SeFL" />
    <child
      link="ThFL" />
    <axis
      xyz="0 0 -1" />
    <limit
      lower="-2.0944"
      upper="2.0944"
      effort="1.471"
      velocity="5.8178" />
    <dynamics
      damping="0.02"
      friction="0.1" />
    <safety_controller
      soft_upper_limit="2.05"
      soft_lower_limit="-2.05"
      k_velocity="0" />
  </joint>
  <link
    name="ArFL">
    <inertial>
      <origin
        xyz="2.7735E-05 -0.007627 0.0033028"
        rpy="0 0 0" />
      <mass
        value="0.0030347" />
      <inertia
        ixx="2.989E-07"
        ixy="4.865E-09"
        ixz="-2.5487E-11"
        iyy="4.3267E-08"
        iyz="5.0977E-09"
        izz="3.2577E-07" />
    </inertial>
    <visual>
      <origin
        xyz="0 0 0"
        rpy="0 0 0" />
      <geometry>
        <mesh
          filename="package://Cerberus/meshes/ArFL.STL" />
      </geometry>
      <material
        name="">
        <color
          rgba="0.89804 0.91765 0.92941 1" />
        <texture
          filename="package://Cerberus/textures/MetalSteel.png" />
      </material>
    </visual>
    <collision>
      <origin
        xyz="0 0 0"
        rpy="0 0 0" />
      <geometry>
        <mesh
          filename="package://Cerberus/meshes/ArFL.STL" />
      </geometry>
    </collision>
  </link>
  <joint
    name="ArFL_ThFL"
    type="revolute">
    <origin
      xyz="-0.050268 -0.027324 0.025077"
      rpy="-1.5708 0 -3.1416" />
    <parent
      link="ThFL" />
    <child
      link="ArFL" />
    <axis
      xyz="0 0 -1" />
    <limit
      lower="-2.0944"
      upper="2.0944"
      effort="1.471"
      velocity="5.8178" />
    <dynamics
      damping="0.02"
      friction="0.1" />
    <safety_controller
      soft_upper_limit="2.05"
      soft_lower_limit="-2.05"
      k_velocity="0" />
  </joint>
  <link
    name="IMU1FL">
    <inertial>
      <origin
        xyz="0 0 0.0015"
        rpy="0 0 0" />
      <mass
        value="0.0009" />
      <inertia
        ixx="1.755E-08"
        ixy="2.4815E-24"
        ixz="1.1416E-23"
        iyy="3.0675E-08"
        iyz="6.4725E-24"
        izz="4.6875E-08" />
    </inertial>
    <visual>
      <origin
        xyz="0 0 0"
        rpy="0 0 0" />
      <geometry>
        <mesh
          filename="package://Cerberus/meshes/IMU1FL.STL" />
      </geometry>
      <material
        name="">
        <color
          rgba="0 1 0 1" />
      </material>
    </visual>
    <collision>
      <origin
        xyz="0 0 0"
        rpy="0 0 0" />
      <geometry>
        <mesh
          filename="package://Cerberus/meshes/IMU1FL.STL" />
      </geometry>
    </collision>
  </link>
  <joint
    name="IMU1FL_ThFL"
    type="fixed">
    <origin
      xyz="-0.079757 -0.006231 0.04015"
      rpy="0 0 0.077967" />
    <parent
      link="ThFL" />
    <child
      link="IMU1FL" />
    <axis
      xyz="0 0 0" />
  </joint>
  <link
    name="ShFL">
    <inertial>
      <origin
        xyz="0.065758 -0.007629 0.014841"
        rpy="0 0 0" />
      <mass
        value="0.10028" />
      <inertia
        ixx="1.1372E-05"
        ixy="2.0704E-05"
        ixz="4.5005E-09"
        iyy="0.00027852"
        iyz="-1.4244E-10"
        izz="0.00028532" />
    </inertial>
    <visual>
      <origin
        xyz="0 0 0"
        rpy="0 0 0" />
      <geometry>
        <mesh
          filename="package://Cerberus/meshes/ShFL.STL" />
      </geometry>
      <material
        name="">
        <color
          rgba="0.50196 0.50196 0.50196 1" />
        <texture
          filename="package://Cerberus/textures/DarkBlackPlastic.png" />
      </material>
    </visual>
    <collision>
      <origin
        xyz="0 0 0"
        rpy="0 0 0" />
      <geometry>
        <mesh
          filename="package://Cerberus/meshes/ShFL.STL" />
      </geometry>
    </collision>
  </link>
  <joint
    name="ShFL_ThFL"
    type="revolute">
    <origin
      xyz="-0.18101 0.0059195 0.01015"
      rpy="0 0 1.6483" />
    <parent
      link="ThFL" />
    <child
      link="ShFL" />
    <axis
      xyz="0 0 -1" />
    <limit
      lower="-2.0944"
      upper="2.0944"
      effort="1.471"
      velocity="5.8178" />
    <dynamics
      damping="0.02"
      friction="0.1" />
    <safety_controller
      soft_upper_limit="2.05"
      soft_lower_limit="-2.05"
      k_velocity="0" />
    <mimic
      joint="ArFL_ThFL"
      multiplier="-0.304"
      offset="0" />
  </joint>
  <link
    name="IMU2FL">
    <inertial>
      <origin
        xyz="0 -2.7756E-17 0.0015"
        rpy="0 0 0" />
      <mass
        value="0.0009" />
      <inertia
        ixx="1.755E-08"
        ixy="-2.4298E-24"
        ixz="9.5499E-24"
        iyy="3.0675E-08"
        iyz="4.1377E-24"
        izz="4.6875E-08" />
    </inertial>
    <visual>
      <origin
        xyz="0 0 0"
        rpy="0 0 0" />
      <geometry>
        <mesh
          filename="package://Cerberus/meshes/IMU2FL.STL" />
      </geometry>
      <material
        name="">
        <color
          rgba="0 1 0 1" />
      </material>
    </visual>
    <collision>
      <origin
        xyz="0 0 0"
        rpy="0 0 0" />
      <geometry>
        <mesh
          filename="package://Cerberus/meshes/IMU2FL.STL" />
      </geometry>
    </collision>
  </link>
  <joint
    name="IMU2FL_ShFL"
    type="fixed">
    <origin
      xyz="0.16803 0.013888 0.024775"
      rpy="0 0 -2.3788" />
    <parent
      link="ShFL" />
    <child
      link="IMU2FL" />
    <axis
      xyz="0 0 0" />
  </joint>
  <link
    name="SeBL">
    <inertial>
      <origin
        xyz="0 0 0"
        rpy="0 0 0" />
      <mass
        value="0" />
      <inertia
        ixx="0"
        ixy="0"
        ixz="0"
        iyy="0"
        iyz="0"
        izz="0" />
    </inertial>
    <visual>
      <origin
        xyz="0 0 0"
        rpy="0 0 0" />
      <geometry>
        <mesh
          filename="package://Cerberus/meshes/SeBL.STL" />
      </geometry>
      <material
        name="">
        <color
          rgba="1 1 1 1" />
        <texture
          filename="package://Cerberus/textures/DarkBlackPlastic.png" />
      </material>
    </visual>
    <collision>
      <origin
        xyz="0 0 0"
        rpy="0 0 0" />
      <geometry>
        <mesh
          filename="package://Cerberus/meshes/SeBL.STL" />
      </geometry>
    </collision>
  </link>
  <joint
    name="SeBL_M"
    type="revolute">
    <origin
      xyz="-0.0904 0.095 0.044"
      rpy="0 -1.5707 -3.1416" />
    <parent
      link="M" />
    <child
      link="SeBL" />
    <axis
      xyz="0.00011373 0 -1" />
    <limit
      lower="-2.0944"
      upper="2.0944"
      effort="1.471"
      velocity="5.8178" />
    <dynamics
      damping="0.02"
      friction="0.1" />
    <safety_controller
      soft_upper_limit="2.05"
      soft_lower_limit="-2.05"
      k_velocity="0" />
  </joint>
  <link
    name="ThBL">
    <inertial>
      <origin
        xyz="-0.065617 -0.006527 0.024441"
        rpy="0 0 0" />
      <mass
        value="0.24964" />
      <inertia
        ixx="5.1153E-05"
        ixy="-2.3468E-05"
        ixz="5.239E-06"
        iyy="0.00072109"
        iyz="-7.8973E-07"
        izz="0.00073416" />
    </inertial>
    <visual>
      <origin
        xyz="0 0 0"
        rpy="0 0 0" />
      <geometry>
        <mesh
          filename="package://Cerberus/meshes/ThBL.STL" />
      </geometry>
      <material
        name="">
        <color
          rgba="0.62745 0.62745 0.62745 1" />
        <texture
          filename="package://Cerberus/textures/DarkBlackPlastic.png" />
      </material>
    </visual>
    <collision>
      <origin
        xyz="0 0 0"
        rpy="0 0 0" />
      <geometry>
        <mesh
          filename="package://Cerberus/meshes/ThBL.STL" />
      </geometry>
    </collision>
  </link>
  <joint
    name="ThBL_SeBL"
    type="revolute">
    <origin
      xyz="2.2896E-05 -0.0144 0.045901"
      rpy="1.5708 -0.70743 0" />
    <parent
      link="SeBL" />
    <child
      link="ThBL" />
    <axis
      xyz="0 0 -1" />
    <limit
      lower="-2.0944"
      upper="2.0944"
      effort="1.471"
      velocity="5.8178" />
    <dynamics
      damping="0.02"
      friction="0.1" />
    <safety_controller
      soft_upper_limit="2.05"
      soft_lower_limit="-2.05"
      k_velocity="0" />
  </joint>
  <link
    name="ArBL">
    <inertial>
      <origin
        xyz="2.7735E-05 -0.007627 0.0033028"
        rpy="0 0 0" />
      <mass
        value="0.0030347" />
      <inertia
        ixx="2.989E-07"
        ixy="4.865E-09"
        ixz="-2.5487E-11"
        iyy="4.3267E-08"
        iyz="5.0977E-09"
        izz="3.2577E-07" />
    </inertial>
    <visual>
      <origin
        xyz="0 0 0"
        rpy="0 0 0" />
      <geometry>
        <mesh
          filename="package://Cerberus/meshes/ArBL.STL" />
      </geometry>
      <material
        name="">
        <color
          rgba="0.89804 0.91765 0.92941 1" />
        <texture
          filename="package://Cerberus/textures/MetalSteel.png" />
      </material>
    </visual>
    <collision>
      <origin
        xyz="0 0 0"
        rpy="0 0 0" />
      <geometry>
        <mesh
          filename="package://Cerberus/meshes/ArBL.STL" />
      </geometry>
    </collision>
  </link>
  <joint
    name="ArBL_ThBL"
    type="revolute">
    <origin
      xyz="-0.050268 -0.027324 0.025077"
      rpy="-1.5708 0 -3.1416" />
    <parent
      link="ThBL" />
    <child
      link="ArBL" />
    <axis
      xyz="0 0 -1" />
    <limit
      lower="-2.0944"
      upper="2.0944"
      effort="1.471"
      velocity="5.8178" />
    <dynamics
      damping="0.02"
      friction="0.1" />
    <safety_controller
      soft_upper_limit="2.05"
      soft_lower_limit="-2.05"
      k_velocity="0" />
  </joint>
  <link
    name="IMU1BL">
    <inertial>
      <origin
        xyz="0 0 0.0015"
        rpy="0 0 0" />
      <mass
        value="0.0009" />
      <inertia
        ixx="1.755E-08"
        ixy="2.4815E-24"
        ixz="1.1416E-23"
        iyy="3.0675E-08"
        iyz="6.4725E-24"
        izz="4.6875E-08" />
    </inertial>
    <visual>
      <origin
        xyz="0 0 0"
        rpy="0 0 0" />
      <geometry>
        <mesh
          filename="package://Cerberus/meshes/IMU1BL.STL" />
      </geometry>
      <material
        name="">
        <color
          rgba="0 1 0 1" />
      </material>
    </visual>
    <collision>
      <origin
        xyz="0 0 0"
        rpy="0 0 0" />
      <geometry>
        <mesh
          filename="package://Cerberus/meshes/IMU1BL.STL" />
      </geometry>
    </collision>
  </link>
  <joint
    name="IMU1BL_ThBL"
    type="fixed">
    <origin
      xyz="-0.079757 -0.006231 0.04015"
      rpy="0 0 0.077967" />
    <parent
      link="ThBL" />
    <child
      link="IMU1BL" />
    <axis
      xyz="0 0 0" />
  </joint>
  <link
    name="ShBL">
    <inertial>
      <origin
        xyz="0.065758 -0.007629 0.014841"
        rpy="0 0 0" />
      <mass
        value="0.10028" />
      <inertia
        ixx="1.1372E-05"
        ixy="2.0704E-05"
        ixz="4.5006E-09"
        iyy="0.00027852"
        iyz="-1.4247E-10"
        izz="0.00028532" />
    </inertial>
    <visual>
      <origin
        xyz="0 0 0"
        rpy="0 0 0" />
      <geometry>
        <mesh
          filename="package://Cerberus/meshes/ShBL.STL" />
      </geometry>
      <material
        name="">
        <color
          rgba="0.50196 0.50196 0.50196 1" />
        <texture
          filename="package://Cerberus/textures/DarkBlackPlastic.png" />
      </material>
    </visual>
    <collision>
      <origin
        xyz="0 0 0"
        rpy="0 0 0" />
      <geometry>
        <mesh
          filename="package://Cerberus/meshes/ShBL.STL" />
      </geometry>
    </collision>
  </link>
  <joint
    name="ShBL_ThBL"
    type="revolute">
    <origin
      xyz="-0.18101 0.0059195 0.01015"
      rpy="0 0 1.6483" />
    <parent
      link="ThBL" />
    <child
      link="ShBL" />
    <axis
      xyz="0 0 -1" />
    <limit
      lower="-2.0944"
      upper="2.0944"
      effort="1.471"
      velocity="5.8178" />
    <dynamics
      damping="0.02"
      friction="0.1" />
    <safety_controller
      soft_upper_limit="2.05"
      soft_lower_limit="-2.05"
      k_velocity="0" />
    <mimic
      joint="ArBL_ThBL"
      multiplier="-0.304"
      offset="0" />
  </joint>
  <link
    name="IMU2BL">
    <inertial>
      <origin
        xyz="2.7756E-17 1.3878E-17 0.0015"
        rpy="0 0 0" />
      <mass
        value="0.0009" />
      <inertia
        ixx="1.755E-08"
        ixy="-1.2666E-23"
        ixz="9.5589E-24"
        iyy="3.0675E-08"
        iyz="1.7655E-24"
        izz="4.6875E-08" />
    </inertial>
    <visual>
      <origin
        xyz="0 0 0"
        rpy="0 0 0" />
      <geometry>
        <mesh
          filename="package://Cerberus/meshes/IMU2BL.STL" />
      </geometry>
      <material
        name="">
        <color
          rgba="0 1 0 1" />
      </material>
    </visual>
    <collision>
      <origin
        xyz="0 0 0"
        rpy="0 0 0" />
      <geometry>
        <mesh
          filename="package://Cerberus/meshes/IMU2BL.STL" />
      </geometry>
    </collision>
  </link>
  <joint
    name="IMU2BL_ShBL"
    type="fixed">
    <origin
      xyz="0.16803 0.013888 0.024775"
      rpy="0 0 -2.3788" />
    <parent
      link="ShBL" />
    <child
      link="IMU2BL" />
    <axis
      xyz="0 0 0" />
  </joint>
</robot>